Workbook

Sheet PD
A1: Primera División | I1: =TODAY() -> 46104
A2: NO. | B2: NOMBRE | C2: APELLIDOS | D2: VIGENCIA | F2: SALARIO MENSUAL | G2: Tipo de Cambio | H2: ESTATUS | I2: DÍAS RESTANTES DE CONTRATO
A3: 1 | B3: Eduardo Daniel | C3: Aguirre Lara | D3: Clausura 2024 | E3: 45473 | F3: 875000 | G3: N/A | H3: =E3-$I$1 -> -631 | I3: =H3 -> -631
A4: 2 | B4: Gaddi Axel | C4: Aguirre Ledesma | D4: Apertura 2026 | E4: 46387 | F4: 354166.67 | G4: N/A | H4: =E4-$I$1 -> 283 | I4: =H4 -> 283
A5: 3 | B5: Abraham | C5: Bass Flores | D5: Clausura 2025 | E5: 45838 | F5: 35000 | G5: N/A | H5: =E5-$I$1 -> -266 | I5: =H5 -> -266
A6: 4 | B6: Jordy Josué | C6: Caicedo Medina | D6: Clausura 2028 | E6: 46934 | F6: 1038333.3 | G6: 17 | H6: =E6-$I$1 -> 830 | I6: =H6 -> 830
A7: 5 | B7: Idekel Alberto | C7: Domínguez Rodríguez | D7: Clausura 2025 | E7: 45838 | F7: 291666.67 | G7: N/A | H7: =E7-$I$1 -> -266 | I7: =H7 -> -266 | J7: * con opción a Apertura 2023
A8: 6 | B8: Raymundo de Jesús | C8: Fulgencio Román | D8: Apertura 2024 | E8: 45657 | F8: 350000 | G8: N/A | H8: =E8-$I$1 -> -447 | I8: =H8 -> -447 | Q8: *Opción a CV definitiva
A9: 7 | B9: Mateo Ezequiel | C9: García | D9: Clausura 2027 | E9: 46568 | F9: 656250 | G9: 17.5 | H9: =E9-$I$1 -> 464 | I9: =H9 -> 464
A10: 8 | B10: Jorge Luis | C10: Guzmán Rodríguez | D10: Apertura 2025 | E10: 46022 | F10: 34000 | G10: N/A | H10: =E10-$I$1 -> -82 | I10: =H10 -> -82
A11: 9 | B11: José Santiago | C11: Hernández García | D11: Clausura 2025 | E11: 45838 | F11: 214583.33 | G11: N/A | H11: =E11-$I$1 -> -266 | I11: =H11 -> -266
A12: 10 | B12: Brian Avelino | C12: Lozano Aparicio | D12: Apertura 2025 | E12: 46022 | F12: 1083333.3 | G12: N/A | H12: =E12-$I$1 -> -82 | I12: =H12 -> -82
A13: 11 | B13: José Rivaldo | C13: Lozano Silva | D13: Apertura 2027 | E13: 46752 | F13: 180000 | G13: N/A | H13: =E13-$I$1 -> 648 | I13: =H13 -> 648
A14: 12 | B14: Mauro Andrés | C14: Manotas Páez | D14: Clausura 2026 | E14: 46203 | F14: 1200000 | G14: 20 | H14: =E14-$I$1 -> 99 | I14: =H14 -> 99
A15: 13 | B15: Ángel Jeremy | C15: Márquez Castañeda | D15: Apertura 2026 | E15: 46387 | F15: 333333.33 | G15: N/A | H15: =E15-$I$1 -> 283 | I15: =H15 -> 283
A16: 14 | B16: Jhon Eduard | C16: Murillo Romaña | D16: Apertura 2024 | E16: 45657 | F16: 1000000 | G16: N/A | H16: =E16-$I$1 -> -447 | I16: =H16 -> -447 | Q16: *Opción a CV definitiva
A17: 15 | B17: Hugo Martín | C17: Nervo | D17: Apertura 2024 | E17: 45657 | F17: 1416666.7 | G17: N/A | H17: =E17-$I$1 -> -447 | I17: =H17 -> -447 | J17: GO
A18: 16 | B18: Luis Ricardo | C18: Reyes Moreno | D18: Apertura 2024 | E18: 45657 | F18: 726000 | G18: N/A | H18: =E18-$I$1 -> -447 | I18: =H18 -> -447
A19: 17 | B19: Carlos Alejandro | C19: Robles Jiménez | D19: Apertura 2027 | E19: 46752 | F19: 80000 | G19: N/A | H19: =E19-$I$1 -> 648 | I19: =H19 -> 648
A20: 18 | B20: Aldo Paul | C20: Rocha González | D20: Clausura 2026 | E20: 46203 | F20: 1750000 | G20: N/A | H20: =E20-$I$1 -> 99 | I20: =H20 -> 99
A21: 19 | B21: Anderson | C21: Santamaría Bardales | D21: Apertura 2025 | E21: 46022 | F21: 1291666.7 | G21: N/A | H21: =E21-$I$1 -> -82 | I21: =H21 -> -82 | J21: *Acumulativo 100% a partir 01/07/2022
A22: 20 | B22: Augusto Jorge Mateo | C22: Solari | D22: Clausura 2025 | E22: 45838 | F22: 927272.73 | G22: 17 | H22: =E22-$I$1 -> -266 | I22: =H22 -> -266
A23: 21 | B23: Christopher Brayan | C23: Trejo Morantes | D23: Clausura 2025 | E23: 45838 | F23: 240833.33 | G23: N/A | H23: =E23-$I$1 -> -266 | I23: =H23 -> -266 | J23: *Vigencia pendiente de registro
A24: 22 | B24: Camilo Andrés | C24: Vargas Gil | D24: Clausura 2026 | E24: 46203 | F24: 1288541.7 | G24: N/A | H24: =E24-$I$1 -> 99 | I24: =H24 -> 99
A25: 23 | B25: Edgar | C25: Zaldivar Valverde | D25: Apertura 2026 | E25: 46387 | F25: 479166.67 | G25: N/A | H25: =E25-$I$1 -> 283 | I25: =H25 -> 283
A26: 24 | B26: Juan Manuel | C26: Zapata Zumaque | D26: Clausura 2024 | E26: 45473 | F26: 280000 | G26: N/A | H26: =E26-$I$1 -> -631 | I26: =H26 -> -631 | Q26: *Opción a CV definitiva
A28: JUGADORES A PRÉSTAMO PRIMERA DIVISIÓN E INTERNACIONAL
A29: NO. | B29: NOMBRE | C29: APELLIDOS | D29: VIGENCIA CONTRATO | F29: VIGENCIA DEL PRÉSTAMO | G29: Club | H29: ESTATUS | I29: DÍAS RESTANTES DE CONTRATO
A30: 1 | B30: Alonso | C30: Ramírez Jiménez | D30: Apertura 2025 | E30: 46022 | F30: AP 2024 | G30: Austin FC | H30: =E30-$I$1 -> -82 | I30: =H30 -> -82 | J30: =F30-'Sub18'!$K$1 -> #VALUE! | K30: =J30 -> #VALUE! | L30: ='Sub18'!$K$1-H30 -> 46186 | M30: =L30/365 -> 126.53699 | N30: =_xlfn.FLOOR.MATH(M30) -> 126 | O30: =L30-(N30*365) -> 196 | P30: =_xlfn.FLOOR.MATH(O30/30) -> 6 | Q30: GO / *Opción a CV definitiva
A31: 2 | B31: Edison Michael | C31: Flores Peralta | D31: Clausura 2026 | E31: 46203 | F31: AP 2024 | G31: Universitario Perú | H31: =E31-$I$1 -> 99 | I31: =H31 -> 99
A32: 3 | B32: José Javier | C32: Abella Fanjul | D32: Clausura 2025 | E32: 45838 | F32: AP 2024 | G32: Juárez FC | H32: =E32-$I$1 -> -266 | I32: =H32 -> -266 | Q32: *Opción a CV definitiva

Sheet Préstamo Expansión
A1: JUGADORES A PRÉSTAMO LIGA EXPANSIÓN | I1: =TODAY() -> 46104
A2: NO. | B2: NOMBRE | C2: APELLIDOS | D2: VIGENCIA CONTRATO | F2: Club | G2: VIGENCIA DEL PRÉSTAMO | H2: ESTATUS | I2: DÍAS RESTANTES DE CONTRATO
A3: 1 | B3: Jairo Ezequiel | C3: Mungaray López | D3: Clausura 2025 | E3: 45838 | F3: Tepatitlán FC | G3: CL 2024 | H3: =E3-'Sub23'!$K$1 -> -266 | I3: =H3 -> -266
A4: 2 | B4: Joel Gustavo | C4: Pérez Valle | D4: Clausura 2025 | E4: 45838 | F4: Club Celaya | G4: CL 2024 | H4: =E4-$I$1 -> -266 | I4: =H4 -> -266 | J4: GO
A5: 3 | B5: Jesús Fabián | C5: Salas Hernández | D5: Clausura 2025 | E5: 45838 | F5: Correcaminos | G5: CL 2024 | H5: =E5-PD!$I$1 -> -266 | I5: =H5 -> -266 | J5: GO
A6: 4 | B6: Antonio | C6: Sánchez Montes de Oca | D6: Apertura 2025 | E6: 46022 | F6: Correcaminos | G6: CL 2024 | H6: =E6-PD!$I$1 -> -82 | I6: =H6 -> -82

Sheet Sub23
A1: Sub 23 | K1: =TODAY() -> 46104
A2: NO. | B2: NOMBRE | C2: APELLIDOS | D2: NUI | E2: VIGENCIA | G2: SALARIO (MENSUAL) | H2: FECHA DE NACIMIENTO | I2: EDAD | J2: ESTATUS | K2: DÍAS RESTANTES DE CONTRATO
A3: 1 | B3: Sergio | C3: Álvarez López | E3: Clausura 2024 | F3: 45473 | G3: 8000 | H3: 38274 | I3: =_xlfn.FLOOR.MATH(M3)&" años "&P3&" meses" -> 21 años 5 meses | J3: =F3-'Sub18'!$K$1 -> -631 | K3: =J3 -> -631 | L3: ='Sub18'!$K$1-H3 -> 7830 | M3: =L3/365 -> 21.452055 | N3: =_xlfn.FLOOR.MATH(M3) -> 21 | O3: =L3-(N3*365) -> 165 | P3: =_xlfn.FLOOR.MATH(O3/30) -> 5
A4: 2 | B4: Edson Amaury | C4: Arce Balleza | E4: Clausura 2024 | F4: 45473 | G4: 8000 | H4: 37567 | I4: =_xlfn.FLOOR.MATH(M4)&" años "&P4&" meses" -> 23 años 4 meses | J4: =F4-$K$1 -> -631 | K4: =J4 -> -631 | L4: =$K$1-H4 -> 8537 | M4: =L4/365 -> 23.389041 | N4: =_xlfn.FLOOR.MATH(M4) -> 23 | O4: =L4-(N4*365) -> 142 | P4: =_xlfn.FLOOR.MATH(O4/30) -> 4
A5: 3 | B5: Roberto Emanuel | C5: Barragán Casillas | E5: Clausura 2025 | F5: 45838 | G5: 8000 | H5: 37993 | I5: =_xlfn.FLOOR.MATH(M5)&" años "&P5&" meses" -> 22 años 2 meses | J5: =F5-'Sub18'!$K$1 -> -266 | K5: =J5 -> -266 | L5: ='Sub18'!$K$1-H5 -> 8111 | M5: =L5/365 -> 22.221918 | N5: =_xlfn.FLOOR.MATH(M5) -> 22 | O5: =L5-(N5*365) -> 81 | P5: =_xlfn.FLOOR.MATH(O5/30) -> 2
A6: 4 | B6: Alejandro de Jesús | C6: Bravo Santiago | E6: Clausura 2024 | F6: 45473 | G6: 10000 | H6: 37703 | I6: =_xlfn.FLOOR.MATH(M6)&" años "&P6&" meses" -> 23 años 0 meses | J6: =F6-$K$1 -> -631 | K6: =J6 -> -631 | L6: =$K$1-H6 -> 8401 | M6: =L6/365 -> 23.016438 | N6: =_xlfn.FLOOR.MATH(M6) -> 23 | O6: =L6-(N6*365) -> 6 | P6: =_xlfn.FLOOR.MATH(O6/30) -> 0 | Q6: GO
A7: 5 | B7: Daniel Xavier | C7: Cervantes Michel | E7: Clausura 2025 | F7: 45838 | G7: 8000 | H7: 37846 | I7: =_xlfn.FLOOR.MATH(M7)&" años "&P7&" meses" -> 22 años 7 meses | J7: =F7-'Sub18'!$K$1 -> -266 | K7: =J7 -> -266 | L7: ='Sub18'!$K$1-H7 -> 8258 | M7: =L7/365 -> 22.624658 | N7: =_xlfn.FLOOR.MATH(M7) -> 22 | O7: =L7-(N7*365) -> 228 | P7: =_xlfn.FLOOR.MATH(O7/30) -> 7 | Q7: CFD
A8: 6 | B8: Leonardo Jair | C8: Correa Moreno | E8: Clausura 2025 | F8: 45838 | G8: 10000 | H8: 37264 | I8: =_xlfn.FLOOR.MATH(M8)&" años "&P8&" meses" -> 24 años 2 meses | J8: =F8-$K$1 -> -266 | K8: =J8 -> -266 | L8: =$K$1-H8 -> 8840 | M8: =L8/365 -> 24.219178 | N8: =_xlfn.FLOOR.MATH(M8) -> 24 | O8: =L8-(N8*365) -> 80 | P8: =_xlfn.FLOOR.MATH(O8/30) -> 2 | Q8: GO
A9: 7 | B9: Carlos Eduardo | C9: Cruz Guillen | E9: Apertura 2026 | F9: 46387 | G9: 8000 | H9: 37996 | I9: =_xlfn.FLOOR.MATH(M9)&" años "&P9&" meses" -> 18 años 9 meses | J9: =F9-[1]Sub18!$K$1 -> 1547 | K9: =J9 -> 1547 | L9: =[1]Sub18!$K$1-H9 -> 6844 | M9: =L9/365 -> 18.750685 | N9: =_xlfn.FLOOR.MATH(M9) -> 18 | O9: =L9-(N9*365) -> 274 | P9: =_xlfn.FLOOR.MATH(O9/30) -> 9 | Q9: GO
A10: 8 | B10: Luis Alberto | C10: Egurrola Valle | E10: Clausura 2024 | F10: 45473 | G10: 8000 | H10: 38058 | I10: =_xlfn.FLOOR.MATH(M10)&" años "&P10&" meses" -> 22 años 0 meses | J10: =F10-'Sub18'!$K$1 -> -631 | K10: =J10 -> -631 | L10: ='Sub18'!$K$1-H10 -> 8046 | M10: =L10/365 -> 22.043836 | N10: =_xlfn.FLOOR.MATH(M10) -> 22 | O10: =L10-(N10*365) -> 16 | P10: =_xlfn.FLOOR.MATH(O10/30) -> 0
A11: 9 | B11: Luis Armando | C11: Flores Gómez | E11: Clausura 2025 | F11: 45838 | G11: 18666 | H11: 36909 | I11: =_xlfn.FLOOR.MATH(M11)&" años "&P11&" meses" -> 25 años 2 meses | J11: =F11-$K$1 -> -266 | K11: =J11 -> -266 | L11: =$K$1-H11 -> 9195 | M11: =L11/365 -> 25.191781 | N11: =_xlfn.FLOOR.MATH(M11) -> 25 | O11: =L11-(N11*365) -> 70 | P11: =_xlfn.FLOOR.MATH(O11/30) -> 2 | Q11: GO
A12: 10 | B12: Ángel de Jesús | C12: García German | E12: Apertura 2024 | F12: 45657 | G12: 9000 | H12: 37750 | I12: =_xlfn.FLOOR.MATH(M12)&" años "&P12&" meses" -> 20 años 9 meses | J12: =F12-[2]Sub18!$K$1 -> 308 | K12: =J12 -> 308 | L12: =[2]Sub18!$K$1-H12 -> 7599 | M12: =L12/365 -> 20.819178 | N12: =_xlfn.FLOOR.MATH(M12) -> 20 | O12: =L12-(N12*365) -> 299 | P12: =_xlfn.FLOOR.MATH(O12/30) -> 9 | Q12: GO
A13: 11 | B13: Rodolfo Andrés | C13: Garza Soto | E13: Clausura 2025 | F13: 45838 | G13: 9000 | H13: 37672 | I13: =_xlfn.FLOOR.MATH(M13)&" años "&P13&" meses" -> 23 años 1 meses | J13: =F13-'Sub18'!$K$1 -> -266 | K13: =J13 -> -266 | L13: ='Sub18'!$K$1-H13 -> 8432 | M13: =L13/365 -> 23.10137 | N13: =_xlfn.FLOOR.MATH(M13) -> 23 | O13: =L13-(N13*365) -> 37 | P13: =_xlfn.FLOOR.MATH(O13/30) -> 1 | Q13: GO
A14: 12 | B14: Sergio Ismael | C14: Hernández Flores | E14: Clausura 2024 | F14: 45473 | G14: 8000 | H14: 38109 | I14: =_xlfn.FLOOR.MATH(M14)&" años "&P14&" meses" -> 21 años 11 meses | J14: =F14-'Sub18'!$K$1 -> -631 | K14: =J14 -> -631 | L14: ='Sub18'!$K$1-H14 -> 7995 | M14: =L14/365 -> 21.90411 | N14: =_xlfn.FLOOR.MATH(M14) -> 21 | O14: =L14-(N14*365) -> 330 | P14: =_xlfn.FLOOR.MATH(O14/30) -> 11
A15: 13 | B15: Antero Manuel | C15: Landaverde González | E15: Apertura 2025 | F15: 46022 | G15: 9000 | H15: 37987 | I15: =_xlfn.FLOOR.MATH(M15)&" años "&P15&" meses" -> 22 años 2 meses | J15: =F15-'Sub18'!$K$1 -> -82 | K15: =J15 -> -82 | L15: ='Sub18'!$K$1-H15 -> 8117 | M15: =L15/365 -> 22.238356 | N15: =_xlfn.FLOOR.MATH(M15) -> 22 | O15: =L15-(N15*365) -> 87 | P15: =_xlfn.FLOOR.MATH(O15/30) -> 2 | Q15: GO
A16: 14 | B16: Israel Alejandro | C16: Larios López | E16: Clausura 2025 | F16: 45838 | G16: 11500 | H16: 37752 | I16: =_xlfn.FLOOR.MATH(M16)&" años "&P16&" meses" -> 22 años 10 meses | J16: =F16-'Sub18'!$K$1 -> -266 | K16: =J16 -> -266 | L16: ='Sub18'!$K$1-H16 -> 8352 | M16: =L16/365 -> 22.882192 | N16: =_xlfn.FLOOR.MATH(M16) -> 22 | O16: =L16-(N16*365) -> 322 | P16: =_xlfn.FLOOR.MATH(O16/30) -> 10 | Q16: GO *Acumulativo
A17: 15 | B17: Juan Jesús | C17: Martín Quiroz | E17: Clausura 2024 | F17: 45473 | G17: 8000 | H17: 37769 | I17: =_xlfn.FLOOR.MATH(M17)&" años "&P17&" meses" -> 0 años meses | J17: =F17-'Sub18'!$K$1 -> -631 | K17: =J17 -> -631
A18: 16 | B18: Luis Gustavo | C18: Martínez Armas | E18: Clausura 2024 | F18: 45473 | G18: 15000 | H18: 37408 | I18: =_xlfn.FLOOR.MATH(M18)&" años "&P18&" meses" -> 23 años 10 meses | J18: =F18-$K$1 -> -631 | K18: =J18 -> -631 | L18: ='Sub18'!$K$1-H18 -> 8696 | M18: =L18/365 -> 23.824658 | N18: =_xlfn.FLOOR.MATH(M18) -> 23 | O18: =L18-(N18*365) -> 301 | P18: =_xlfn.FLOOR.MATH(O18/30) -> 10 | Q18: GO
A19: 17 | B19: Rafael | C19: Martínez Ortega | E19: Clausura 2025 | F19: 45838 | G19: 15000 | H19: 37541 | I19: =_xlfn.FLOOR.MATH(M19)&" años "&P19&" meses" -> 23 años 5 meses | J19: =F19-$K$1 -> -266 | K19: =J19 -> -266 | L19: ='Sub18'!$K$1-H19 -> 8563 | M19: =L19/365 -> 23.460274 | N19: =_xlfn.FLOOR.MATH(M19) -> 23 | O19: =L19-(N19*365) -> 168 | P19: =_xlfn.FLOOR.MATH(O19/30) -> 5 | Q19: GO
A20: 18 | B20: Eduardo | C20: Moreno Cervantes | E20: Clausura 2025 | F20: 45838 | G20: 9000 | H20: 37955 | I20: =_xlfn.FLOOR.MATH(M20)&" años "&P20&" meses" -> 22 años 3 meses | J20: =F20-'Sub18'!$K$1 -> -266 | K20: =J20 -> -266 | L20: ='Sub18'!$K$1-H20 -> 8149 | M20: =L20/365 -> 22.326027 | N20: =_xlfn.FLOOR.MATH(M20) -> 22 | O20: =L20-(N20*365) -> 119 | P20: =_xlfn.FLOOR.MATH(O20/30) -> 3 | Q20: GO
A21: 19 | B21: Leonardo | C21: Pérez Maldonado Martínez | E21: Clausura 2025 | F21: 45838 | G21: 8000 | H21: 38054 | I21: =_xlfn.FLOOR.MATH(M21)&" años "&P21&" meses" -> 19 años 12 meses | J21: =F21-[2]Sub16!$K$1 -> 489 | K21: =J21 -> 489 | L21: =[2]Sub16!$K$1-H21 -> 7295 | M21: =L21/365 -> 19.986301 | N21: =_xlfn.FLOOR.MATH(M21) -> 19 | O21: =L21-(N21*365) -> 360 | P21: =_xlfn.FLOOR.MATH(O21/30) -> 12
A22: 20 | B22: Paulo | C22: Ramírez Barboza | E22: Clausura 2025 | F22: 45838 | G22: 8000 | H22: 37910 | I22: =_xlfn.FLOOR.MATH(M22)&" años "&P22&" meses" -> 22 años 5 meses | J22: =F22-$K$1 -> -266 | K22: =J22 -> -266 | L22: =$K$1-H22 -> 8194 | M22: =L22/365 -> 22.449315 | N22: =_xlfn.FLOOR.MATH(M22) -> 22 | O22: =L22-(N22*365) -> 164 | P22: =_xlfn.FLOOR.MATH(O22/30) -> 5
A23: 21 | B23: Víctor Hugo | C23: Ríos de Alba | E23: Apertura 2026 | F23: 46387 | G23: 9833.33 | H23: 38028 | I23: =_xlfn.FLOOR.MATH(M23)&" años "&P23&" meses" -> 22 años 1 meses | J23: =F23-'Sub18'!$K$1 -> 283 | K23: =J23 -> 283 | L23: ='Sub18'!$K$1-H23 -> 8076 | M23: =L23/365 -> 22.126027 | N23: =_xlfn.FLOOR.MATH(M23) -> 22 | O23: =L23-(N23*365) -> 46 | P23: =_xlfn.FLOOR.MATH(O23/30) -> 1 | Q23: GO *Ya debutó en AP 23
A24: 22 | B24: Jorge Alessandro | C24: San Martín Hernández | E24: Apertura 2025 | F24: 46022 | G24: 8000 | H24: 38209 | I24: =_xlfn.FLOOR.MATH(M24)&" años "&P24&" meses" -> 21 años 7 meses | J24: =F24-'Sub18'!$K$1 -> -82 | K24: =J24 -> -82 | L24: ='Sub18'!$K$1-H24 -> 7895 | M24: =L24/365 -> 21.630137 | N24: =_xlfn.FLOOR.MATH(M24) -> 21 | O24: =L24-(N24*365) -> 230 | P24: =_xlfn.FLOOR.MATH(O24/30) -> 7 | Q24: GO

Sheet Sub18
A1: Sub 18 | K1: =TODAY() -> 46104
A2: NO. | B2: NOMBRE | C2: APELLIDOS | D2: NUI | E2: VIGENCIA | G2: SALARIO (MENSUAL) | H2: FECHA DE NACIMIENTO | I2: EDAD | J2: ESTATUS | K2: DÍAS RESTANTES DE CONTRATO
A3: 1 | B3: Álvaro Alonso | C3: Beas Castro | E3: Clausura 2025 | F3: 45838 | G3: 7470 | H3: 38641 | I3: =_xlfn.FLOOR.MATH(M3)&" años "&P3&" meses" -> 20 años 5 meses | J3: =F3-$K$1 -> -266 | K3: =J3 -> -266 | L3: =$K$1-H3 -> 7463 | M3: =L3/365 -> 20.446575 | N3: =_xlfn.FLOOR.MATH(M3) -> 20 | O3: =L3-(N3*365) -> 163 | P3: =_xlfn.FLOOR.MATH(O3/30) -> 5
A4: 2 | B4: Luis Elie | C4: Blanco Pérez | E4: Clausura 2025 | F4: 45838 | G4: 7470 | H4: 38740 | I4: =_xlfn.FLOOR.MATH(M4)&" años "&P4&" meses" -> 20 años 2 meses | J4: =F4-'Sub16'!$K$1 -> -266 | K4: =J4 -> -266 | L4: ='Sub16'!$K$1-H4 -> 7364 | M4: =L4/365 -> 20.175342 | N4: =_xlfn.FLOOR.MATH(M4) -> 20 | O4: =L4-(N4*365) -> 64 | P4: =_xlfn.FLOOR.MATH(O4/30) -> 2
A5: 3 | B5: Adrián | C5: Cabrera Rodríguez | E5: Clausura 2025 | F5: 45838 | G5: 7470 | H5: 38764 | I5: =_xlfn.FLOOR.MATH(M5)&" años "&P5&" meses" -> 20 años 1 meses | J5: =F5-$K$1 -> -266 | K5: =J5 -> -266 | L5: =$K$1-H5 -> 7340 | M5: =L5/365 -> 20.109589 | N5: =_xlfn.FLOOR.MATH(M5) -> 20 | O5: =L5-(N5*365) -> 40 | P5: =_xlfn.FLOOR.MATH(O5/30) -> 1
A6: 4 | B6: Diego Alejandro | C6: Calleja Melesio | E6: Clausura 2025 | F6: 45838 | G6: 7470 | H6: 38411 | I6: =_xlfn.FLOOR.MATH(M6)&" años "&P6&" meses" -> 21 años 0 meses | J6: =F6-$K$1 -> -266 | K6: =J6 -> -266 | L6: =$K$1-H6 -> 7693 | M6: =L6/365 -> 21.076712 | N6: =_xlfn.FLOOR.MATH(M6) -> 21 | O6: =L6-(N6*365) -> 28 | P6: =_xlfn.FLOOR.MATH(O6/30) -> 0
A7: 5 | B7: Ricardo | C7: Cuevas Capitaine | E7: Clausura 2025 | F7: 45838 | G7: 7470 | H7: 38652 | I7: =_xlfn.FLOOR.MATH(M7)&" años "&P7&" meses" -> 20 años 5 meses | J7: =F7-'Sub16'!$K$1 -> -266 | K7: =J7 -> -266 | L7: ='Sub16'!$K$1-H7 -> 7452 | M7: =L7/365 -> 20.416438 | N7: =_xlfn.FLOOR.MATH(M7) -> 20 | O7: =L7-(N7*365) -> 152 | P7: =_xlfn.FLOOR.MATH(O7/30) -> 5
A8: 6 | B8: José Gael | C8: Gómez Carrión | E8: Clausura 2025 | F8: 45838 | G8: 7470 | H8: 38551 | I8: =_xlfn.FLOOR.MATH(M8)&" años "&P8&" meses" -> 20 años 8 meses | J8: =F8-'Sub16'!$K$1 -> -266 | K8: =J8 -> -266 | L8: ='Sub16'!$K$1-H8 -> 7553 | M8: =L8/365 -> 20.693151 | N8: =_xlfn.FLOOR.MATH(M8) -> 20 | O8: =L8-(N8*365) -> 253 | P8: =_xlfn.FLOOR.MATH(O8/30) -> 8
A9: 7 | B9: Gerardo Gabriel | C9: Gómez Lara | E9: Clausura 2025 | F9: 45838 | G9: 7470 | H9: 38779 | I9: =_xlfn.FLOOR.MATH(M9)&" años "&P9&" meses" -> 20 años 0 meses | J9: =F9-'Sub16'!$K$1 -> -266 | K9: =J9 -> -266 | L9: ='Sub16'!$K$1-H9 -> 7325 | M9: =L9/365 -> 20.068493 | N9: =_xlfn.FLOOR.MATH(M9) -> 20 | O9: =L9-(N9*365) -> 25 | P9: =_xlfn.FLOOR.MATH(O9/30) -> 0
A10: 8 | B10: Juan Carlos | C10: González Contreras | E10: Clausura 2025 | F10: 45838 | G10: 7470 | H10: 38480 | I10: =_xlfn.FLOOR.MATH(M10)&" años "&P10&" meses" -> 20 años 10 meses | J10: =F10-'Sub16'!$K$1 -> -266 | K10: =J10 -> -266 | L10: ='Sub16'!$K$1-H10 -> 7624 | M10: =L10/365 -> 20.887671 | N10: =_xlfn.FLOOR.MATH(M10) -> 20 | O10: =L10-(N10*365) -> 324 | P10: =_xlfn.FLOOR.MATH(O10/30) -> 10
A11: 9 | B11: Jesús Eloy | C11: Guillen Ávila | E11: Clausura 2026 | F11: 46203 | G11: 7470 | H11: 38524 | I11: =_xlfn.FLOOR.MATH(M11)&" años "&P11&" meses" -> 20 años 9 meses | J11: =F11-'Sub16'!$K$1 -> 99 | K11: =J11 -> 99 | L11: ='Sub16'!$K$1-H11 -> 7580 | M11: =L11/365 -> 20.767123 | N11: =_xlfn.FLOOR.MATH(M11) -> 20 | O11: =L11-(N11*365) -> 280 | P11: =_xlfn.FLOOR.MATH(O11/30) -> 9
A12: 10 | B12: Carlos Jesús | C12: Henríquez Andrade | E12: Clausura 2025 | F12: 45838 | G12: 7470 | H12: 38458 | I12: =_xlfn.FLOOR.MATH(M12)&" años "&P12&" meses" -> 20 años 11 meses | J12: =F12-$K$1 -> -266 | K12: =J12 -> -266 | L12: =$K$1-H12 -> 7646 | M12: =L12/365 -> 20.947945 | N12: =_xlfn.FLOOR.MATH(M12) -> 20 | O12: =L12-(N12*365) -> 346 | P12: =_xlfn.FLOOR.MATH(O12/30) -> 11
A13: 11 | B13: Luis Fernando | C13: Hernández Maza | E13: Clausura 2025 | F13: 45838 | G13: 7470 | H13: 38832 | I13: =_xlfn.FLOOR.MATH(M13)&" años "&P13&" meses" -> 19 años 11 meses | J13: =F13-'Sub16'!$K$1 -> -266 | K13: =J13 -> -266 | L13: ='Sub16'!$K$1-H13 -> 7272 | M13: =L13/365 -> 19.923288 | N13: =_xlfn.FLOOR.MATH(M13) -> 19 | O13: =L13-(N13*365) -> 337 | P13: =_xlfn.FLOOR.MATH(O13/30) -> 11
A14: 12 | B14: Miguel Isaí | C14: Hernández Rodríguez | E14: Clausura 2026 | F14: 45473 | G14: 7470 | H14: 38674 | I14: =_xlfn.FLOOR.MATH(M14)&" años "&P14&" meses" -> 20 años 4 meses | J14: =F14-'Sub16'!$K$1 -> -631 | K14: =J14 -> -631 | L14: ='Sub16'!$K$1-H14 -> 7430 | M14: =L14/365 -> 20.356164 | N14: =_xlfn.FLOOR.MATH(M14) -> 20 | O14: =L14-(N14*365) -> 130 | P14: =_xlfn.FLOOR.MATH(O14/30) -> 4
A15: 13 | B15: Óscar Emiliano | C15: Hidalgo Sánchez | E15: Clausura 2025 | F15: 45838 | G15: 7470 | H15: 38607 | I15: =_xlfn.FLOOR.MATH(M15)&" años "&P15&" meses" -> 20 años 6 meses | J15: =F15-'Sub16'!$K$1 -> -266 | K15: =J15 -> -266 | L15: ='Sub16'!$K$1-H15 -> 7497 | M15: =L15/365 -> 20.539726 | N15: =_xlfn.FLOOR.MATH(M15) -> 20 | O15: =L15-(N15*365) -> 197 | P15: =_xlfn.FLOOR.MATH(O15/30) -> 6
A16: 14 | B16: Guadalupe Noel | C16: Lara Rodríguez | E16: Clausura 2025 | F16: 45838 | G16: 0 | H16: 38868 | I16: =_xlfn.FLOOR.MATH(M16)&" años "&P16&" meses" -> 19 años 10 meses | J16: =F16-'Sub16'!$K$1 -> -266 | K16: =J16 -> -266 | L16: ='Sub16'!$K$1-H16 -> 7236 | M16: =L16/365 -> 19.824658 | N16: =_xlfn.FLOOR.MATH(M16) -> 19 | O16: =L16-(N16*365) -> 301 | P16: =_xlfn.FLOOR.MATH(O16/30) -> 10 | Q16: CFD
A17: 15 | B17: Héctor Alejandro | C17: Medina Barreto | E17: Clausura 2025 | F17: 45838 | G17: 7470 | H17: 38546 | I17: =_xlfn.FLOOR.MATH(M17)&" años "&P17&" meses" -> 20 años 8 meses | J17: =F17-$K$1 -> -266 | K17: =J17 -> -266 | L17: =$K$1-H17 -> 7558 | M17: =L17/365 -> 20.706849 | N17: =_xlfn.FLOOR.MATH(M17) -> 20 | O17: =L17-(N17*365) -> 258 | P17: =_xlfn.FLOOR.MATH(O17/30) -> 8
A18: 16 | B18: Axel Uriel | C18: Oñate Hernández | E18: Clausura 2025 | F18: 45838 | G18: 0 | H18: 38542 | I18: =_xlfn.FLOOR.MATH(M18)&" años "&P18&" meses" -> 20 años 8 meses | J18: =F18-$K$1 -> -266 | K18: =J18 -> -266 | L18: =$K$1-H18 -> 7562 | M18: =L18/365 -> 20.717808 | N18: =_xlfn.FLOOR.MATH(M18) -> 20 | O18: =L18-(N18*365) -> 262 | P18: =_xlfn.FLOOR.MATH(O18/30) -> 8 | Q18: CFD
A19: 17 | B19: Brandon Daniel | C19: Ortiz Covarrubias | E19: Clausura 2025 | F19: 45838 | G19: 7470 | H19: 38390 | I19: =_xlfn.FLOOR.MATH(M19)&" años "&P19&" meses" -> 21 años 1 meses | J19: =F19-$K$1 -> -266 | K19: =J19 -> -266 | L19: =$K$1-H19 -> 7714 | M19: =L19/365 -> 21.134247 | N19: =_xlfn.FLOOR.MATH(M19) -> 21 | O19: =L19-(N19*365) -> 49 | P19: =_xlfn.FLOOR.MATH(O19/30) -> 1
A20: 18 | B20: Óscar Trinidad | C20: Reyes Urtiaga | E20: Clausura 2025 | F20: 45838 | G20: 7470 | H20: 38517 | I20: =_xlfn.FLOOR.MATH(M20)&" años "&P20&" meses" -> 20 años 9 meses | J20: =F20-'Sub16'!$K$1 -> -266 | K20: =J20 -> -266 | L20: ='Sub16'!$K$1-H20 -> 7587 | M20: =L20/365 -> 20.786301 | N20: =_xlfn.FLOOR.MATH(M20) -> 20 | O20: =L20-(N20*365) -> 287 | P20: =_xlfn.FLOOR.MATH(O20/30) -> 9
A21: 19 | B21: Alonso | C21: Ripoll Magaña | E21: Clausura 2025 | F21: 45838 | G21: 7470 | H21: 38377 | I21: =_xlfn.FLOOR.MATH(M21)&" años "&P21&" meses" -> 21 años 2 meses | J21: =F21-$K$1 -> -266 | K21: =J21 -> -266 | L21: =$K$1-H21 -> 7727 | M21: =L21/365 -> 21.169863 | N21: =_xlfn.FLOOR.MATH(M21) -> 21 | O21: =L21-(N21*365) -> 62 | P21: =_xlfn.FLOOR.MATH(O21/30) -> 2
A22: 20 | B22: Paolo | C22: Romero Sosa | E22: Clausura 2025 | F22: 45838 | G22: 7470 | H22: 38476 | I22: =_xlfn.FLOOR.MATH(M22)&" años "&P22&" meses" -> 20 años 10 meses | J22: =F22-'Sub16'!$K$1 -> -266 | K22: =J22 -> -266 | L22: ='Sub16'!$K$1-H22 -> 7628 | M22: =L22/365 -> 20.89863 | N22: =_xlfn.FLOOR.MATH(M22) -> 20 | O22: =L22-(N22*365) -> 328 | P22: =_xlfn.FLOOR.MATH(O22/30) -> 10
A23: 21 | B23: Ricardo Isaías | C23: Santana Pérez | E23: Clausura 2025 | F23: 45838 | G23: 7470 | H23: 38408 | I23: =_xlfn.FLOOR.MATH(M23)&" años "&P23&" meses" -> 21 años 1 meses | J23: =F23-'Sub16'!$K$1 -> -266 | K23: =J23 -> -266 | L23: ='Sub16'!$K$1-H23 -> 7696 | M23: =L23/365 -> 21.084932 | N23: =_xlfn.FLOOR.MATH(M23) -> 21 | O23: =L23-(N23*365) -> 31 | P23: =_xlfn.FLOOR.MATH(O23/30) -> 1
A24: 22 | B24: Jesús Eduardo | C24: Serrato Zambrano | E24: Clausura 2026 | F24: 45838 | G24: 7470 | H24: 38707 | I24: =_xlfn.FLOOR.MATH(M24)&" años "&P24&" meses" -> 20 años 3 meses | J24: =F24-$K$1 -> -266 | K24: =J24 -> -266 | L24: =$K$1-H24 -> 7397 | M24: =L24/365 -> 20.265753 | N24: =_xlfn.FLOOR.MATH(M24) -> 20 | O24: =L24-(N24*365) -> 97 | P24: =_xlfn.FLOOR.MATH(O24/30) -> 3
A25: 23 | B25: Ángel Jesús | C25: Sevilla Montoya | E25: Clausura 2025 | F25: 45838 | G25: 7470 | H25: 38727 | I25: =_xlfn.FLOOR.MATH(M25)&" años "&P25&" meses" -> 20 años 2 meses | J25: =F25-$K$1 -> -266 | K25: =J25 -> -266 | L25: =$K$1-H25 -> 7377 | M25: =L25/365 -> 20.210959 | N25: =_xlfn.FLOOR.MATH(M25) -> 20 | O25: =L25-(N25*365) -> 77 | P25: =_xlfn.FLOOR.MATH(O25/30) -> 2
A26: 24 | B26: Kevin Alexis | C26: Silva | E26: Clausura 2025 | F26: 45838 | G26: 0 | H26: 38795 | I26: =_xlfn.FLOOR.MATH(M26)&" años "&P26&" meses" -> 20 años 0 meses | J26: =F26-'Sub16'!$K$1 -> -266 | K26: =J26 -> -266 | L26: ='Sub16'!$K$1-H26 -> 7309 | M26: =L26/365 -> 20.024658 | N26: =_xlfn.FLOOR.MATH(M26) -> 20 | O26: =L26-(N26*365) -> 9 | P26: =_xlfn.FLOOR.MATH(O26/30) -> 0 | Q26: CFD
A27: 25 | B27: Norberto Carlos | C27: Suárez | E27: Clausura 2025 | F27: 45838 | G27: 0 | H27: 38746 | I27: =_xlfn.FLOOR.MATH(M27)&" años "&P27&" meses" -> 20 años 1 meses | J27: =F27-'Sub16'!$K$1 -> -266 | K27: =J27 -> -266 | L27: ='Sub16'!$K$1-H27 -> 7358 | M27: =L27/365 -> 20.158904 | N27: =_xlfn.FLOOR.MATH(M27) -> 20 | O27: =L27-(N27*365) -> 58 | P27: =_xlfn.FLOOR.MATH(O27/30) -> 1 | Q27: CFD
A28: 26 | B28: Luis Antonio | C28: Suárez López | E28: Clausura 2025 | F28: 45838 | G28: 7470 | H28: 38788 | I28: =_xlfn.FLOOR.MATH(M28)&" años "&P28&" meses" -> 20 años 0 meses | J28: =F28-'Sub16'!$K$1 -> -266 | K28: =J28 -> -266 | L28: ='Sub16'!$K$1-H28 -> 7316 | M28: =L28/365 -> 20.043836 | N28: =_xlfn.FLOOR.MATH(M28) -> 20 | O28: =L28-(N28*365) -> 16 | P28: =_xlfn.FLOOR.MATH(O28/30) -> 0
A29: 27 | B29: Diego Jhovani | C29: Trejo Roldán | E29: Clausura 2025 | F29: 45838 | G29: 7470 | H29: 38822 | I29: =_xlfn.FLOOR.MATH(M29)&" años "&P29&" meses" -> 19 años 11 meses | J29: =F29-$K$1 -> -266 | K29: =J29 -> -266 | L29: =$K$1-H29 -> 7282 | M29: =L29/365 -> 19.950685 | N29: =_xlfn.FLOOR.MATH(M29) -> 19 | O29: =L29-(N29*365) -> 347 | P29: =_xlfn.FLOOR.MATH(O29/30) -> 11
A30: 28 | B30: Eric Fernando | C30: Villegas Rodríguez | E30: Clausura 2025 | F30: 45838 | G30: 7470 | H30: 39024 | I30: =_xlfn.FLOOR.MATH(M30)&" años "&P30&" meses" -> 19 años 4 meses | J30: =F30-'Sub16'!$K$1 -> -266 | K30: =J30 -> -266 | L30: ='Sub16'!$K$1-H30 -> 7080 | M30: =L30/365 -> 19.39726 | N30: =_xlfn.FLOOR.MATH(M30) -> 19 | O30: =L30-(N30*365) -> 145 | P30: =_xlfn.FLOOR.MATH(O30/30) -> 4
A31: 29 | B31: Dylan Alejandro | C31: Zamora Orozco | E31: Clausura 2025 | F31: 45838 | G31: 7470 | H31: 38810 | I31: =_xlfn.FLOOR.MATH(M31)&" años "&P31&" meses" -> 19 años 11 meses | J31: =F31-'Sub16'!$K$1 -> -266 | K31: =J31 -> -266 | L31: ='Sub16'!$K$1-H31 -> 7294 | M31: =L31/365 -> 19.983562 | N31: =_xlfn.FLOOR.MATH(M31) -> 19 | O31: =L31-(N31*365) -> 359 | P31: =_xlfn.FLOOR.MATH(O31/30) -> 11

Sheet Sub16
A1: Sub 16 | K1: =TODAY() -> 46104
A2: NO. | B2: NOMBRE | C2: APELLIDOS | D2: NUI | E2: VIGENCIA | G2: SALARIO (MENSUAL) | H2: FECHA DE NACIMIENTO | I2: EDAD | J2: ESTATUS | K2: DÍAS RESTANTES DE CONTRATO
A3: 1 | B3: Jesús Nazareth | C3: Aguirre Márquez | E3: Clausura 2025 | F3: 45838 | G3: 0 | H3: 39247 | I3: =_xlfn.FLOOR.MATH(M3)&" años "&P3&" meses" -> 18 años 9 meses | J3: =F3-$K$1 -> -266 | K3: =J3 -> -266 | L3: =$K$1-H3 -> 6857 | M3: =L3/365 -> 18.786301 | N3: =_xlfn.FLOOR.MATH(M3) -> 18 | O3: =L3-(N3*365) -> 287 | P3: =_xlfn.FLOOR.MATH(O3/30) -> 9
A4: 2 | B4: Anthony Owen | C4: Bautista Príncipe | E4: Clausura 2025 | F4: 45838 | G4: 0 | H4: 39235 | I4: =_xlfn.FLOOR.MATH(M4)&" años "&P4&" meses" -> 18 años 9 meses | J4: =F4-'Sub14'!$K$1 -> -266 | K4: =J4 -> -266 | L4: ='Sub14'!$K$1-H4 -> 6869 | M4: =L4/365 -> 18.819178 | N4: =_xlfn.FLOOR.MATH(M4) -> 18 | O4: =L4-(N4*365) -> 299 | P4: =_xlfn.FLOOR.MATH(O4/30) -> 9
A5: 3 | B5: Fabio | C5: Caballe Loeza | E5: Clausura 2025 | F5: 45838 | G5: 0 | H5: 39346 | I5: =_xlfn.FLOOR.MATH(M5)&" años "&P5&" meses" -> 18 años 6 meses | J5: =F5-'Sub14'!$K$1 -> -266 | K5: =J5 -> -266 | L5: ='Sub14'!$K$1-H5 -> 6758 | M5: =L5/365 -> 18.515068 | N5: =_xlfn.FLOOR.MATH(M5) -> 18 | O5: =L5-(N5*365) -> 188 | P5: =_xlfn.FLOOR.MATH(O5/30) -> 6
A6: 4 | B6: Rodrigo Alberto | C6: Cárdenas Campos | E6: Clausura 2025 | F6: 45838 | G6: 0 | H6: 39145 | I6: =_xlfn.FLOOR.MATH(M6)&" años "&P6&" meses" -> 19 años 0 meses | J6: =F6-'Sub14'!$K$1 -> -266 | K6: =J6 -> -266 | L6: ='Sub14'!$K$1-H6 -> 6959 | M6: =L6/365 -> 19.065753 | N6: =_xlfn.FLOOR.MATH(M6) -> 19 | O6: =L6-(N6*365) -> 24 | P6: =_xlfn.FLOOR.MATH(O6/30) -> 0
A7: 5 | B7: Abraham Alejandro | C7: Cárdenas Ochoa | E7: Clausura 2025 | F7: 45838 | G7: 0 | H7: 39501 | I7: =_xlfn.FLOOR.MATH(M7)&" años "&P7&" meses" -> 18 años 1 meses | J7: =F7-'Sub14'!$K$1 -> -266 | K7: =J7 -> -266 | L7: ='Sub14'!$K$1-H7 -> 6603 | M7: =L7/365 -> 18.090411 | N7: =_xlfn.FLOOR.MATH(M7) -> 18 | O7: =L7-(N7*365) -> 33 | P7: =_xlfn.FLOOR.MATH(O7/30) -> 1
A8: 6 | B8: Mariano | C8: Castañeda Casian | E8: Clausura 2025 | F8: 45838 | G8: 0 | H8: 39095 | I8: =_xlfn.FLOOR.MATH(M8)&" años "&P8&" meses" -> 19 años 2 meses | J8: =F8-'Sub14'!$K$1 -> -266 | K8: =J8 -> -266 | L8: ='Sub14'!$K$1-H8 -> 7009 | M8: =L8/365 -> 19.20274 | N8: =_xlfn.FLOOR.MATH(M8) -> 19 | O8: =L8-(N8*365) -> 74 | P8: =_xlfn.FLOOR.MATH(O8/30) -> 2
A9: 7 | B9: Dylan Yandel | C9: Cortéz Pintor | E9: Apertura 2025 | F9: 46022 | G9: 0 | H9: 39770 | I9: =_xlfn.FLOOR.MATH(M9)&" años "&P9&" meses" -> 17 años 4 meses | J9: =F9-'Sub14'!$K$1 -> -82 | K9: =J9 -> -82 | L9: ='Sub14'!$K$1-H9 -> 6334 | M9: =L9/365 -> 17.353425 | N9: =_xlfn.FLOOR.MATH(M9) -> 17 | O9: =L9-(N9*365) -> 129 | P9: =_xlfn.FLOOR.MATH(O9/30) -> 4 | Q9: *Asociación Jalisco
A10: 8 | B10: Milton Nicolás | C10: Esponda Castillo | E10: Clausura 2025 | F10: 45838 | G10: 0 | H10: 39302 | I10: =_xlfn.FLOOR.MATH(M10)&" años "&P10&" meses" -> 18 años 7 meses | J10: =F10-'Sub14'!$K$1 -> -266 | K10: =J10 -> -266 | L10: ='Sub14'!$K$1-H10 -> 6802 | M10: =L10/365 -> 18.635616 | N10: =_xlfn.FLOOR.MATH(M10) -> 18 | O10: =L10-(N10*365) -> 232 | P10: =_xlfn.FLOOR.MATH(O10/30) -> 7
A11: 9 | B11: Hernán Patricio | C11: Estrada Miramontes | E11: Clausura 2025 | F11: 45838 | G11: 0 | H11: 39462 | I11: =_xlfn.FLOOR.MATH(M11)&" años "&P11&" meses" -> 18 años 2 meses | J11: =F11-'Sub14'!$K$1 -> -266 | K11: =J11 -> -266 | L11: ='Sub14'!$K$1-H11 -> 6642 | M11: =L11/365 -> 18.19726 | N11: =_xlfn.FLOOR.MATH(M11) -> 18 | O11: =L11-(N11*365) -> 72 | P11: =_xlfn.FLOOR.MATH(O11/30) -> 2
A12: 10 | B12: Valentín | C12: Galindo Rodríguez | E12: Clausura 2025 | F12: 45838 | G12: 0 | H12: 39137 | I12: =_xlfn.FLOOR.MATH(M12)&" años "&P12&" meses" -> 19 años 1 meses | J12: =F12-'Sub14'!$K$1 -> -266 | K12: =J12 -> -266 | L12: ='Sub14'!$K$1-H12 -> 6967 | M12: =L12/365 -> 19.087671 | N12: =_xlfn.FLOOR.MATH(M12) -> 19 | O12: =L12-(N12*365) -> 32 | P12: =_xlfn.FLOOR.MATH(O12/30) -> 1
A13: 11 | B13: Luis Mario | C13: Gamboa Carrillo | E13: Clausura 2025 | F13: 45838 | G13: 0 | H13: 39746 | I13: =_xlfn.FLOOR.MATH(M13)&" años "&P13&" meses" -> 17 años 5 meses | J13: =F13-'Sub14'!$K$1 -> -266 | K13: =J13 -> -266 | L13: ='Sub14'!$K$1-H13 -> 6358 | M13: =L13/365 -> 17.419178 | N13: =_xlfn.FLOOR.MATH(M13) -> 17 | O13: =L13-(N13*365) -> 153 | P13: =_xlfn.FLOOR.MATH(O13/30) -> 5
A14: 12 | B14: Gibrán Emiliano | C14: García Núñez | E14: Clausura 2025 | F14: 45838 | G14: 0 | H14: 39171 | I14: =_xlfn.FLOOR.MATH(M14)&" años "&P14&" meses" -> 18 años 12 meses | J14: =F14-'Sub14'!$K$1 -> -266 | K14: =J14 -> -266 | L14: ='Sub14'!$K$1-H14 -> 6933 | M14: =L14/365 -> 18.994521 | N14: =_xlfn.FLOOR.MATH(M14) -> 18 | O14: =L14-(N14*365) -> 363 | P14: =_xlfn.FLOOR.MATH(O14/30) -> 12
A15: 13 | B15: Santiago | C15: Grageda Calderón | E15: Apertura 2024 | F15: 45657 | G15: 0 | H15: 39754 | I15: =_xlfn.FLOOR.MATH(M15)&" años "&P15&" meses" -> 17 años 4 meses | J15: =F15-'Sub14'!$K$1 -> -447 | K15: =J15 -> -447 | L15: ='Sub14'!$K$1-H15 -> 6350 | M15: =L15/365 -> 17.39726 | N15: =_xlfn.FLOOR.MATH(M15) -> 17 | O15: =L15-(N15*365) -> 145 | P15: =_xlfn.FLOOR.MATH(O15/30) -> 4
A16: 14 | B16: Carlos Raúl | C16: Hernández Moreno | E16: Clausura 2025 | F16: 45838 | G16: 0 | H16: 39126 | I16: =_xlfn.FLOOR.MATH(M16)&" años "&P16&" meses" -> 19 años 1 meses | J16: =F16-'Sub14'!$K$1 -> -266 | K16: =J16 -> -266 | L16: ='Sub14'!$K$1-H16 -> 6978 | M16: =L16/365 -> 19.117808 | N16: =_xlfn.FLOOR.MATH(M16) -> 19 | O16: =L16-(N16*365) -> 43 | P16: =_xlfn.FLOOR.MATH(O16/30) -> 1
A17: 15 | B17: José Emilio | C17: Ibarra Gutiérrez | E17: Clausura 2025 | F17: 45838 | G17: 0 | H17: 39198 | I17: =_xlfn.FLOOR.MATH(M17)&" años "&P17&" meses" -> 18 años 11 meses | J17: =F17-'Sub14'!$K$1 -> -266 | K17: =J17 -> -266 | L17: ='Sub14'!$K$1-H17 -> 6906 | M17: =L17/365 -> 18.920548 | N17: =_xlfn.FLOOR.MATH(M17) -> 18 | O17: =L17-(N17*365) -> 336 | P17: =_xlfn.FLOOR.MATH(O17/30) -> 11
A18: 16 | B18: Roberto | C18: López Cuadra Arias | E18: Clausura 2026 | F18: 46203 | G18: 0 | H18: 39802 | I18: =_xlfn.FLOOR.MATH(M18)&" años "&P18&" meses" -> 17 años 3 meses | J18: =F18-'Sub14'!$K$1 -> 99 | K18: =J18 -> 99 | L18: ='Sub14'!$K$1-H18 -> 6302 | M18: =L18/365 -> 17.265753 | N18: =_xlfn.FLOOR.MATH(M18) -> 17 | O18: =L18-(N18*365) -> 97 | P18: =_xlfn.FLOOR.MATH(O18/30) -> 3
A19: 17 | B19: Naresh | C19: Lopéz Villanueva | E19: Apertura 2025 | F19: 46022 | G19: 0 | H19: 39515 | I19: =_xlfn.FLOOR.MATH(M19)&" años "&P19&" meses" -> 18 años 0 meses | J19: =F19-'Sub14'!$K$1 -> -82 | K19: =J19 -> -82 | L19: ='Sub14'!$K$1-H19 -> 6589 | M19: =L19/365 -> 18.052055 | N19: =_xlfn.FLOOR.MATH(M19) -> 18 | O19: =L19-(N19*365) -> 19 | P19: =_xlfn.FLOOR.MATH(O19/30) -> 0
A20: 18 | B20: Carlos Ramón | C20: Luquin Rodríguez | E20: Clausura 2025 | F20: 45838 | G20: 0 | H20: 39506 | I20: =_xlfn.FLOOR.MATH(M20)&" años "&P20&" meses" -> 18 años 0 meses | J20: =F20-'Sub14'!$K$1 -> -266 | K20: =J20 -> -266 | L20: ='Sub14'!$K$1-H20 -> 6598 | M20: =L20/365 -> 18.076712 | N20: =_xlfn.FLOOR.MATH(M20) -> 18 | O20: =L20-(N20*365) -> 28 | P20: =_xlfn.FLOOR.MATH(O20/30) -> 0
A21: 19 | B21: Sebastián Axael | C21: Mandujano | E21: Clausura 2025 | F21: 45838 | G21: 0 | H21: 39137 | I21: =_xlfn.FLOOR.MATH(M21)&" años "&P21&" meses" -> 19 años 1 meses | J21: =F21-'Sub14'!$K$1 -> -266 | K21: =J21 -> -266 | L21: ='Sub14'!$K$1-H21 -> 6967 | M21: =L21/365 -> 19.087671 | N21: =_xlfn.FLOOR.MATH(M21) -> 19 | O21: =L21-(N21*365) -> 32 | P21: =_xlfn.FLOOR.MATH(O21/30) -> 1
... A23: 21 | B23: Donato Fermin | C23: Marín Villagómez | E23: Clausura 2025 | F23: 45838 | G23: 0 | H23: 39487 | I23: =_xlfn.FLOOR.MATH(M23)&" años "&P23&" meses" -> 18 años 1 meses | J23: =F23-'Sub14'!$K$1 -> -266 | K23: =J23 -> -266 | L23: ='Sub14'!$K$1-H23 -> 6617 | M23: =L23/365 -> 18.128767 | N23: =_xlfn.FLOOR.MATH(M23) -> 18 | O23: =L23-(N23*365) -> 47 | P23: =_xlfn.FLOOR.MATH(O23/30) -> 1
A24: 22 | B24: José Luis | C24: Martín Sánchez | E24: Clausura 2025 | F24: 45838 | G24: 0 | H24: 39221 | I24: =_xlfn.FLOOR.MATH(M24)&" años "&P24&" meses" -> 18 años 10 meses | J24: =F24-$K$1 -> -266 | K24: =J24 -> -266 | L24: =$K$1-H24 -> 6883 | M24: =L24/365 -> 18.857534 | N24: =_xlfn.FLOOR.MATH(M24) -> 18 | O24: =L24-(N24*365) -> 313 | P24: =_xlfn.FLOOR.MATH(O24/30) -> 10
A25: 23 | B25: Emilio | C25: Martínez Horta | E25: Clausura 2025 | F25: 45838 | G25: 0 | H25: 39637 | I25: =_xlfn.FLOOR.MATH(M25)&" años "&P25&" meses" -> 17 años 8 meses | J25: =F25-'Sub14'!$K$1 -> -266 | K25: =J25 -> -266 | L25: ='Sub14'!$K$1-H25 -> 6467 | M25: =L25/365 -> 17.717808 | N25: =_xlfn.FLOOR.MATH(M25) -> 17 | O25: =L25-(N25*365) -> 262 | P25: =_xlfn.FLOOR.MATH(O25/30) -> 8
A26: 24 | B26: David Emiliano | C26: Murillo Díaz | E26: Clausura 2025 | F26: 45838 | G26: 0 | H26: 39368 | I26: =_xlfn.FLOOR.MATH(M26)&" años "&P26&" meses" -> 18 años 5 meses | J26: =F26-'Sub14'!$K$1 -> -266 | K26: =J26 -> -266 | L26: ='Sub14'!$K$1-H26 -> 6736 | M26: =L26/365 -> 18.454795 | N26: =_xlfn.FLOOR.MATH(M26) -> 18 | O26: =L26-(N26*365) -> 166 | P26: =_xlfn.FLOOR.MATH(O26/30) -> 5
A27: 25 | B27: Aldo Giovanni | C27: Navarro Álvarez | E27: Clausura 2025 | F27: 45838 | G27: 0 | H27: 39196 | I27: =_xlfn.FLOOR.MATH(M27)&" años "&P27&" meses" -> 18 años 11 meses | J27: =F27-'Sub14'!$K$1 -> -266 | K27: =J27 -> -266 | L27: ='Sub14'!$K$1-H27 -> 6908 | M27: =L27/365 -> 18.926027 | N27: =_xlfn.FLOOR.MATH(M27) -> 18 | O27: =L27-(N27*365) -> 338 | P27: =_xlfn.FLOOR.MATH(O27/30) -> 11
A28: 26 | B28: Adriano Naelson | C28: Pantoja Reyes | E28: Apertura 2024 | F28: 45657 | G28: 0 | H28: 39774 | I28: =_xlfn.FLOOR.MATH(M28)&" años "&P28&" meses" -> 17 años 4 meses | J28: =F28-'Sub14'!$K$1 -> -447 | K28: =J28 -> -447 | L28: ='Sub14'!$K$1-H28 -> 6330 | M28: =L28/365 -> 17.342466 | N28: =_xlfn.FLOOR.MATH(M28) -> 17 | O28: =L28-(N28*365) -> 125 | P28: =_xlfn.FLOOR.MATH(O28/30) -> 4
A29: 27 | B29: Luis Alfonso | C29: Pérez Corona | E29: Clausura 2025 | F29: 45838 | G29: 0 | H29: 39114 | I29: =_xlfn.FLOOR.MATH(M29)&" años "&P29&" meses" -> 19 años 1 meses | J29: =F29-$K$1 -> -266 | K29: =J29 -> -266 | L29: =$K$1-H29 -> 6990 | M29: =L29/365 -> 19.150685 | N29: =_xlfn.FLOOR.MATH(M29) -> 19 | O29: =L29-(N29*365) -> 55 | P29: =_xlfn.FLOOR.MATH(O29/30) -> 1
A30: 28 | B30: Saúl Alejandro | C30: Pérez Veloz | E30: Clausura 2025 | F30: 45838 | G30: 0 | H30: 39567 | I30: =_xlfn.FLOOR.MATH(M30)&" años "&P30&" meses" -> 17 años 11 meses | J30: =F30-'Sub14'!$K$1 -> -266 | K30: =J30 -> -266 | L30: ='Sub14'!$K$1-H30 -> 6537 | M30: =L30/365 -> 17.909589 | N30: =_xlfn.FLOOR.MATH(M30) -> 17 | O30: =L30-(N30*365) -> 332 | P30: =_xlfn.FLOOR.MATH(O30/30) -> 11 | Q30: *Asociación Jalisco
A31: 29 | B31: Diego Tristán | C31: Reyes Gutiérrez | E31: Clausura 2025 | F31: 45838 | G31: 0 | H31: 39116 | I31: =_xlfn.FLOOR.MATH(M31)&" años "&P31&" meses" -> 19 años 1 meses | J31: =F31-'Sub14'!$K$1 -> -266 | K31: =J31 -> -266 | L31: ='Sub14'!$K$1-H31 -> 6988 | M31: =L31/365 -> 19.145205 | N31: =_xlfn.FLOOR.MATH(M31) -> 19 | O31: =L31-(N31*365) -> 53 | P31: =_xlfn.FLOOR.MATH(O31/30) -> 1
A32: 30 | B32: Diego Jair | C32: Rodríguez Cornejo | E32: Clausura 2025 | F32: 45838 | G32: 0 | H32: 39959 | I32: =_xlfn.FLOOR.MATH(M32)&" años "&P32&" meses" -> 16 años 10 meses | J32: =F32-'Sub14'!$K$1 -> -266 | K32: =J32 -> -266 | L32: ='Sub14'!$K$1-H32 -> 6145 | M32: =L32/365 -> 16.835616 | N32: =_xlfn.FLOOR.MATH(M32) -> 16 | O32: =L32-(N32*365) -> 305 | P32: =_xlfn.FLOOR.MATH(O32/30) -> 10 | Q32: *Asociación Jalisco
A33: 31 | B33: Luis Armando | C33: Rodríguez Mendoza | E33: Clausura 2025 | F33: 45838 | G33: 0 | H33: 39270 | I33: =_xlfn.FLOOR.MATH(M33)&" años "&P33&" meses" -> 18 años 8 meses | J33: =F33-'Sub14'!$K$1 -> -266 | K33: =J33 -> -266 | L33: ='Sub14'!$K$1-H33 -> 6834 | M33: =L33/365 -> 18.723288 | N33: =_xlfn.FLOOR.MATH(M33) -> 18 | O33: =L33-(N33*365) -> 264 | P33: =_xlfn.FLOOR.MATH(O33/30) -> 8
A34: 32 | B34: Dominic | C34: Román Espinosa | E34: Clausura 2025 | F34: 45838 | G34: 0 | H34: 39664 | I34: =_xlfn.FLOOR.MATH(M34)&" años "&P34&" meses" -> 17 años 7 meses | J34: =F34-'Sub14'!$K$1 -> -266 | K34: =J34 -> -266 | L34: ='Sub14'!$K$1-H34 -> 6440 | M34: =L34/365 -> 17.643836 | N34: =_xlfn.FLOOR.MATH(M34) -> 17 | O34: =L34-(N34*365) -> 235 | P34: =_xlfn.FLOOR.MATH(O34/30) -> 7
A35: 33 | B35: Raúl | C35: Solís López | E35: Apertura 2024 | F35: 45657 | G35: 0 | H35: 39501 | I35: =_xlfn.FLOOR.MATH(M35)&" años "&P35&" meses" -> 18 años 1 meses | J35: =F35-'Sub14'!$K$1 -> -447 | K35: =J35 -> -447 | L35: ='Sub14'!$K$1-H35 -> 6603 | M35: =L35/365 -> 18.090411 | N35: =_xlfn.FLOOR.MATH(M35) -> 18 | O35: =L35-(N35*365) -> 33 | P35: =_xlfn.FLOOR.MATH(O35/30) -> 1 | Q35: *Asociación Jalisco
A36: 34 | B36: Oscar Apolinar | C36: Trújillo Ramírez | E36: Clausura 2025 | F36: 45838 | G36: 0 | H36: 39092 | I36: =_xlfn.FLOOR.MATH(M36)&" años "&P36&" meses" -> 19 años 2 meses | J36: =F36-'Sub14'!$K$1 -> -266 | K36: =J36 -> -266 | L36: ='Sub14'!$K$1-H36 -> 7012 | M36: =L36/365 -> 19.210959 | N36: =_xlfn.FLOOR.MATH(M36) -> 19 | O36: =L36-(N36*365) -> 77 | P36: =_xlfn.FLOOR.MATH(O36/30) -> 2
A37: 35 | B37: Emilio | C37: Velázquez Bolaños | E37: Clausura 2025 | F37: 45838 | G37: 0 | H37: 39290 | I37: =_xlfn.FLOOR.MATH(M37)&" años "&P37&" meses" -> 18 años 8 meses | J37: =F37-'Sub14'!$K$1 -> -266 | K37: =J37 -> -266 | L37: ='Sub14'!$K$1-H37 -> 6814 | M37: =L37/365 -> 18.668493 | N37: =_xlfn.FLOOR.MATH(M37) -> 18 | O37: =L37-(N37*365) -> 244 | P37: =_xlfn.FLOOR.MATH(O37/30) -> 8
A38: 36 | B38: Lissandro | C38: Ventura Cortés | E38: Clausura 2025 | F38: 45838 | G38: 0 | H38: 39225 | I38: =_xlfn.FLOOR.MATH(M38)&" años "&P38&" meses" -> 18 años 10 meses | J38: =F38-$K$1 -> -266 | K38: =J38 -> -266 | L38: =$K$1-H38 -> 6879 | M38: =L38/365 -> 18.846575 | N38: =_xlfn.FLOOR.MATH(M38) -> 18 | O38: =L38-(N38*365) -> 309 | P38: =_xlfn.FLOOR.MATH(O38/30) -> 10
A39: 37 | B39: Omar Fabricio | C39: Vilchis González | E39: Clausura 2025 | F39: 45838 | G39: 0 | H39: 39264 | I39: =_xlfn.FLOOR.MATH(M39)&" años "&P39&" meses" -> 18 años 9 meses | J39: =F39-'Sub14'!$K$1 -> -266 | K39: =J39 -> -266 | L39: ='Sub14'!$K$1-H39 -> 6840 | M39: =L39/365 -> 18.739726 | N39: =_xlfn.FLOOR.MATH(M39) -> 18 | O39: =L39-(N39*365) -> 270 | P39: =_xlfn.FLOOR.MATH(O39/30) -> 9
A40: 38 | B40: Jhony Rolando | C40: Zúñiga Rentería | E40: Apertura 2024 | F40: 45657 | G40: 0 | H40: 39556 | I40: =_xlfn.FLOOR.MATH(M40)&" años "&P40&" meses" -> 17 años 11 meses | J40: =F40-'Sub14'!$K$1 -> -447 | K40: =J40 -> -447 | L40: ='Sub14'!$K$1-H40 -> 6548 | M40: =L40/365 -> 17.939726 | N40: =_xlfn.FLOOR.MATH(M40) -> 17 | O40: =L40-(N40*365) -> 343 | P40: =_xlfn.FLOOR.MATH(O40/30) -> 11 | Q40: *Asociación Jalisco

Sheet Sub14
A1: Sub 14 | K1: =TODAY() -> 46104
A2: NO. | B2: NOMBRE | C2: APELLIDOS | D2: NUI | E2: VIGENCIA | G2: SALARIO (MENSUAL) | H2: FECHA DE NACIMIENTO | I2: EDAD | J2: ESTATUS | K2: DÍAS RESTANTES DE CONTRATO
A3: 1 | B3: Ángel Alexander | C3: Aguilar Chávez | E3: Clausura 2025 | F3: 45838 | G3: 0 | H3: 39834 | I3: =_xlfn.FLOOR.MATH(M3)&" años "&P3&" meses" -> 17 años 2 meses | J3: =F3-$K$1 -> -266 | K3: =J3 -> -266 | L3: =$K$1-H3 -> 6270 | M3: =L3/365 -> 17.178082 | N3: =_xlfn.FLOOR.MATH(M3) -> 17 | O3: =L3-(N3*365) -> 65 | P3: =_xlfn.FLOOR.MATH(O3/30) -> 2
A4: 2 | B4: Yohan Fabián | C4: Cabrera Rodríguez | E4: Clausura 2025 | F4: 45838 | G4: 0 | H4: 39933 | I4: =_xlfn.FLOOR.MATH(M4)&" años "&P4&" meses" -> 16 años 11 meses | J4: =F4-$K$1 -> -266 | K4: =J4 -> -266 | L4: =$K$1-H4 -> 6171 | M4: =L4/365 -> 16.906849 | N4: =_xlfn.FLOOR.MATH(M4) -> 16 | O4: =L4-(N4*365) -> 331 | P4: =_xlfn.FLOOR.MATH(O4/30) -> 11
A5: 3 | B5: Emiliano | C5: Castellanos Bautista | E5: Apertura 2024 | F5: 45657 | G5: 0 | H5: 39956 | I5: =_xlfn.FLOOR.MATH(M5)&" años "&P5&" meses" -> 16 años 10 meses | J5: =F5-$K$1 -> -447 | K5: =J5 -> -447 | L5: =$K$1-H5 -> 6148 | M5: =L5/365 -> 16.843836 | N5: =_xlfn.FLOOR.MATH(M5) -> 16 | O5: =L5-(N5*365) -> 308 | P5: =_xlfn.FLOOR.MATH(O5/30) -> 10
A6: 4 | B6: Luciano Israel | C6: Castellanos Bautista | E6: Apertura 2024 | F6: 45657 | G6: 0 | H6: 40465 | I6: =_xlfn.FLOOR.MATH(M6)&" años "&P6&" meses" -> 15 años 5 meses | J6: =F6-$K$1 -> -447 | K6: =J6 -> -447 | L6: =$K$1-H6 -> 5639 | M6: =L6/365 -> 15.449315 | N6: =_xlfn.FLOOR.MATH(M6) -> 15 | O6: =L6-(N6*365) -> 164 | P6: =_xlfn.FLOOR.MATH(O6/30) -> 5
A7: 5 | B7: Alejandro | C7: Del Real Quezada | E7: Clausura 2025 | F7: 45838 | G7: 0 | H7: 39987 | I7: =_xlfn.FLOOR.MATH(M7)&" años "&P7&" meses" -> 16 años 9 meses | J7: =F7-$K$1 -> -266 | K7: =J7 -> -266 | L7: =$K$1-H7 -> 6117 | M7: =L7/365 -> 16.758904 | N7: =_xlfn.FLOOR.MATH(M7) -> 16 | O7: =L7-(N7*365) -> 277 | P7: =_xlfn.FLOOR.MATH(O7/30) -> 9
A8: 6 | B8: Leonardo Jesús | C8: Espino Contreras | E8: Clausura 2025 | F8: 45838 | G8: 0 | H8: 40107 | I8: =_xlfn.FLOOR.MATH(M8)&" años "&P8&" meses" -> 16 años 5 meses | J8: =F8-$K$1 -> -266 | K8: =J8 -> -266 | L8: =$K$1-H8 -> 5997 | M8: =L8/365 -> 16.430137 | N8: =_xlfn.FLOOR.MATH(M8) -> 16 | O8: =L8-(N8*365) -> 157 | P8: =_xlfn.FLOOR.MATH(O8/30) -> 5
A9: 7 | B9: César Patricio | C9: Franco Simental | E9: Clausura 2024 | F9: 45473 | G9: 0 | H9: 39557 | I9: =_xlfn.FLOOR.MATH(M9)&" años "&P9&" meses" -> 17 años 11 meses | J9: =F9-$K$1 -> -631 | K9: =J9 -> -631 | L9: =$K$1-H9 -> 6547 | M9: =L9/365 -> 17.936986 | N9: =_xlfn.FLOOR.MATH(M9) -> 17 | O9: =L9-(N9*365) -> 342 | P9: =_xlfn.FLOOR.MATH(O9/30) -> 11 | Q9: *Asociación Jalisco
A10: 8 | B10: Saúl Alexander | C10: García Quezada | E10: Clausura 2025 | F10: 45838 | G10: 0 | H10: 40024 | I10: =_xlfn.FLOOR.MATH(M10)&" años "&P10&" meses" -> 16 años 8 meses | J10: =F10-$K$1 -> -266 | K10: =J10 -> -266 | L10: =$K$1-H10 -> 6080 | M10: =L10/365 -> 16.657534 | N10: =_xlfn.FLOOR.MATH(M10) -> 16 | O10: =L10-(N10*365) -> 240 | P10: =_xlfn.FLOOR.MATH(O10/30) -> 8
A11: 9 | B11: Olmo Ernesto | C11: Godínez Santiago | E11: Clausura 2025 | F11: 45838 | G11: 0 | H11: 39827 | I11: =_xlfn.FLOOR.MATH(M11)&" años "&P11&" meses" -> 17 años 2 meses | J11: =F11-$K$1 -> -266 | K11: =J11 -> -266 | L11: =$K$1-H11 -> 6277 | M11: =L11/365 -> 17.19726 | N11: =_xlfn.FLOOR.MATH(M11) -> 17 | O11: =L11-(N11*365) -> 72 | P11: =_xlfn.FLOOR.MATH(O11/30) -> 2
A12: 10 | B12: Emiliano | C12: Gómez Gómez | E12: Clausura 2025 | F12: 45838 | G12: 0 | H12: 39932 | I12: =_xlfn.FLOOR.MATH(M12)&" años "&P12&" meses" -> 16 años 11 meses | J12: =F12-$K$1 -> -266 | K12: =J12 -> -266 | L12: =$K$1-H12 -> 6172 | M12: =L12/365 -> 16.909589 | N12: =_xlfn.FLOOR.MATH(M12) -> 16 | O12: =L12-(N12*365) -> 332 | P12: =_xlfn.FLOOR.MATH(O12/30) -> 11
A13: 11 | B13: Hugo Maximiliano | C13: González Martínez | E13: Clausura 2024 | F13: 45473 | G13: 0 | H13: 39661 | I13: =_xlfn.FLOOR.MATH(M13)&" años "&P13&" meses" -> 17 años 7 meses | J13: =F13-$K$1 -> -631 | K13: =J13 -> -631 | L13: =$K$1-H13 -> 6443 | M13: =L13/365 -> 17.652055 | N13: =_xlfn.FLOOR.MATH(M13) -> 17 | O13: =L13-(N13*365) -> 238 | P13: =_xlfn.FLOOR.MATH(O13/30) -> 7 | Q13: *Asociación Jalisco
A14: 12 | B14: Santiago | C14: Gutiérrez Cortes | E14: Clausura 2025 | F14: 45838 | G14: 0 | H14: 39857 | I14: =_xlfn.FLOOR.MATH(M14)&" años "&P14&" meses" -> 17 años 1 meses | J14: =F14-$K$1 -> -266 | K14: =J14 -> -266 | L14: =$K$1-H14 -> 6247 | M14: =L14/365 -> 17.115068 | N14: =_xlfn.FLOOR.MATH(M14) -> 17 | O14: =L14-(N14*365) -> 42 | P14: =_xlfn.FLOOR.MATH(O14/30) -> 1
A15: 13 | B15: Erick Daniel | C15: Gutiérrez Padilla | E15: Clausura 2025 | F15: 45838 | G15: 0 | H15: 39904 | I15: =_xlfn.FLOOR.MATH(M15)&" años "&P15&" meses" -> 16 años 12 meses | J15: =F15-$K$1 -> -266 | K15: =J15 -> -266 | L15: =$K$1-H15 -> 6200 | M15: =L15/365 -> 16.986301 | N15: =_xlfn.FLOOR.MATH(M15) -> 16 | O15: =L15-(N15*365) -> 360 | P15: =_xlfn.FLOOR.MATH(O15/30) -> 12
A16: 14 | B16: Orlando Gamaliel | C16: Gutiérrez Villa | E16: Clausura 2026 | F16: 46203 | G16: 0 | H16: 39864 | I16: =_xlfn.FLOOR.MATH(M16)&" años "&P16&" meses" -> 17 años 1 meses | J16: =F16-$K$1 -> 99 | K16: =J16 -> 99 | L16: =$K$1-H16 -> 6240 | M16: =L16/365 -> 17.09589 | N16: =_xlfn.FLOOR.MATH(M16) -> 17 | O16: =L16-(N16*365) -> 35 | P16: =_xlfn.FLOOR.MATH(O16/30) -> 1 | Q16: *Pendiente firma CM
A17: 15 | B17: Leonardo Emmanuel | C17: Hernández Bonilla | E17: Clausura 2026 | F17: 46203 | G17: 0 | H17: 39982 | I17: =_xlfn.FLOOR.MATH(M17)&" años "&P17&" meses" -> 16 años 9 meses | J17: =F17-$K$1 -> 99 | K17: =J17 -> 99 | L17: =$K$1-H17 -> 6122 | M17: =L17/365 -> 16.772603 | N17: =_xlfn.FLOOR.MATH(M17) -> 16 | O17: =L17-(N17*365) -> 282 | P17: =_xlfn.FLOOR.MATH(O17/30) -> 9
A18: 16 | B18: Daniel | C18: Hernández Teran | E18: Clausura 2026 | F18: 46203 | G18: 0 | H18: 39940 | I18: =_xlfn.FLOOR.MATH(M18)&" años "&P18&" meses" -> 16 años 10 meses | J18: =F18-$K$1 -> 99 | K18: =J18 -> 99 | L18: =$K$1-H18 -> 6164 | M18: =L18/365 -> 16.887671 | N18: =_xlfn.FLOOR.MATH(M18) -> 16 | O18: =L18-(N18*365) -> 324 | P18: =_xlfn.FLOOR.MATH(O18/30) -> 10
A19: 17 | B19: Rayhan Emir | C19: Iñiguez Cortéz | E19: Apertura 2024 | F19: 45657 | G19: 0 | H19: 39684 | I19: =_xlfn.FLOOR.MATH(M19)&" años "&P19&" meses" -> 17 años 7 meses | J19: =F19-$K$1 -> -447 | K19: =J19 -> -447 | L19: =$K$1-H19 -> 6420 | M19: =L19/365 -> 17.589041 | N19: =_xlfn.FLOOR.MATH(M19) -> 17 | O19: =L19-(N19*365) -> 215 | P19: =_xlfn.FLOOR.MATH(O19/30) -> 7 | Q19: *Asociación Jalisco
A20: 18 | B20: Daniel | C20: Jiménez Aburto | E20: Apertura 2024 | F20: 45657 | G20: 0 | H20: 39852 | I20: =_xlfn.FLOOR.MATH(M20)&" años "&P20&" meses" -> 17 años 1 meses | J20: =F20-$K$1 -> -447 | K20: =J20 -> -447 | L20: =$K$1-H20 -> 6252 | M20: =L20/365 -> 17.128767 | N20: =_xlfn.FLOOR.MATH(M20) -> 17 | O20: =L20-(N20*365) -> 47 | P20: =_xlfn.FLOOR.MATH(O20/30) -> 1
A21: 19 | B21: Álvaro | C21: Lizárraga Torres | E21: Apertura 2024 | F21: 45657 | G21: 0 | H21: 39826 | I21: =_xlfn.FLOOR.MATH(M21)&" años "&P21&" meses" -> 17 años 2 meses | J21: =F21-$K$1 -> -447 | K21: =J21 -> -447 | L21: =$K$1-H21 -> 6278 | M21: =L21/365 -> 17.2 | N21: =_xlfn.FLOOR.MATH(M21) -> 17 | O21: =L21-(N21*365) -> 73 | P21: =_xlfn.FLOOR.MATH(O21/30) -> 2
A22: 20 | B22: Aaron | C22: López Hernández | E22: Clausura 2025 | F22: 45838 | G22: 0 | H22: 40025 | I22: =_xlfn.FLOOR.MATH(M22)&" años "&P22&" meses" -> 16 años 7 meses | J22: =F22-$K$1 -> -266 | K22: =J22 -> -266 | L22: =$K$1-H22 -> 6079 | M22: =L22/365 -> 16.654795 | N22: =_xlfn.FLOOR.MATH(M22) -> 16 | O22: =L22-(N22*365) -> 239 | P22: =_xlfn.FLOOR.MATH(O22/30) -> 7
A23: 21 | B23: Said Emir | C23: López Sánchez | E23: Clausura 2025 | F23: 45838 | G23: 0 | H23: 39973 | I23: =_xlfn.FLOOR.MATH(M23)&" años "&P23&" meses" -> 16 años 9 meses | J23: =F23-$K$1 -> -266 | K23: =J23 -> -266 | L23: =$K$1-H23 -> 6131 | M23: =L23/365 -> 16.79726 | N23: =_xlfn.FLOOR.MATH(M23) -> 16 | O23: =L23-(N23*365) -> 291 | P23: =_xlfn.FLOOR.MATH(O23/30) -> 9
A24: 22 | B24: Ángel Balam | C24: Macías Romo | E24: Clausura 2025 | F24: 45838 | G24: 0 | H24: 39907 | I24: =_xlfn.FLOOR.MATH(M24)&" años "&P24&" meses" -> 16 años 11 meses | J24: =F24-$K$1 -> -266 | K24: =J24 -> -266 | L24: =$K$1-H24 -> 6197 | M24: =L24/365 -> 16.978082 | N24: =_xlfn.FLOOR.MATH(M24) -> 16 | O24: =L24-(N24*365) -> 357 | P24: =_xlfn.FLOOR.MATH(O24/30) -> 11
A25: 23 | B25: Gabriel | C25: Martínez Sánchez | E25: Clausura 2025 | F25: 45838 | G25: 0 | H25: 39877 | I25: =_xlfn.FLOOR.MATH(M25)&" años "&P25&" meses" -> 17 años 0 meses | J25: =F25-$K$1 -> -266 | K25: =J25 -> -266 | L25: =$K$1-H25 -> 6227 | M25: =L25/365 -> 17.060274 | N25: =_xlfn.FLOOR.MATH(M25) -> 17 | O25: =L25-(N25*365) -> 22 | P25: =_xlfn.FLOOR.MATH(O25/30) -> 0
A26: 24 | B26: Iker Kenneth | C26: Maya Camacho | E26: Apertura 2024 | F26: 45657 | G26: 0 | H26: 39886 | I26: =_xlfn.FLOOR.MATH(M26)&" años "&P26&" meses" -> 17 años 0 meses | J26: =F26-$K$1 -> -447 | K26: =J26 -> -447 | L26: =$K$1-H26 -> 6218 | M26: =L26/365 -> 17.035616 | N26: =_xlfn.FLOOR.MATH(M26) -> 17 | O26: =L26-(N26*365) -> 13 | P26: =_xlfn.FLOOR.MATH(O26/30) -> 0
A27: 25 | B27: Luis Felipe de Jesús | C27: Medina Rodríguez | E27: Clausura 2025 | F27: 45838 | G27: 0 | H27: 39984 | I27: =_xlfn.FLOOR.MATH(M27)&" años "&P27&" meses" -> 16 años 9 meses | J27: =F27-'Sub16'!$K$1 -> -266 | K27: =J27 -> -266 | L27: ='Sub16'!$K$1-H27 -> 6120 | M27: =L27/365 -> 16.767123 | N27: =_xlfn.FLOOR.MATH(M27) -> 16 | O27: =L27-(N27*365) -> 280 | P27: =_xlfn.FLOOR.MATH(O27/30) -> 9 | Q27: *Academia SV
A28: 26 | B28: André Fabián | C28: Morales Solorio | E28: Clausura 2025 | F28: 45838 | G28: 0 | H28: 40333 | I28: =_xlfn.FLOOR.MATH(M28)&" años "&P28&" meses" -> 15 años 9 meses | J28: =F28-$K$1 -> -266 | K28: =J28 -> -266 | L28: =$K$1-H28 -> 5771 | M28: =L28/365 -> 15.810959 | N28: =_xlfn.FLOOR.MATH(M28) -> 15 | O28: =L28-(N28*365) -> 296 | P28: =_xlfn.FLOOR.MATH(O28/30) -> 9
A29: 27 | B29: Noe Tadeo | C29: Mota Aviña | E29: Clausura 2025 | F29: 45838 | G29: 0 | H29: 39924 | I29: =_xlfn.FLOOR.MATH(M29)&" años "&P29&" meses" -> 16 años 11 meses | J29: =F29-$K$1 -> -266 | K29: =J29 -> -266 | L29: =$K$1-H29 -> 6180 | M29: =L29/365 -> 16.931507 | N29: =_xlfn.FLOOR.MATH(M29) -> 16 | O29: =L29-(N29*365) -> 340 | P29: =_xlfn.FLOOR.MATH(O29/30) -> 11
A30: 28 | B30: Donovan Santiago | C30: Muciño Chávez | E30: Apertura 2024 | F30: 45657 | G30: 0 | H30: 39869 | I30: =_xlfn.FLOOR.MATH(M30)&" años "&P30&" meses" -> 17 años 1 meses | J30: =F30-$K$1 -> -447 | K30: =J30 -> -447 | L30: =$K$1-H30 -> 6235 | M30: =L30/365 -> 17.082192 | N30: =_xlfn.FLOOR.MATH(M30) -> 17 | O30: =L30-(N30*365) -> 30 | P30: =_xlfn.FLOOR.MATH(O30/30) -> 1
A31: 29 | B31: Juan Daniel | C31: Nieto Díaz | E31: Apertura 2024 | F31: 45657 | G31: 0 | H31: 39815 | I31: =_xlfn.FLOOR.MATH(M31)&" años "&P31&" meses" -> 17 años 2 meses | J31: =F31-$K$1 -> -447 | K31: =J31 -> -447 | L31: =$K$1-H31 -> 6289 | M31: =L31/365 -> 17.230137 | N31: =_xlfn.FLOOR.MATH(M31) -> 17 | O31: =L31-(N31*365) -> 84 | P31: =_xlfn.FLOOR.MATH(O31/30) -> 2
A32: 30 | B32: Mateo | C32: Reyes Fernández | E32: Clausura 2025 | F32: 45838 | G32: 0 | H32: 40022 | I32: =_xlfn.FLOOR.MATH(M32)&" años "&P32&" meses" -> 16 años 8 meses | J32: =F32-$K$1 -> -266 | K32: =J32 -> -266 | L32: =$K$1-H32 -> 6082 | M32: =L32/365 -> 16.663014 | N32: =_xlfn.FLOOR.MATH(M32) -> 16 | O32: =L32-(N32*365) -> 242 | P32: =_xlfn.FLOOR.MATH(O32/30) -> 8
A33: 31 | B33: Cristofer Jesús | C33: Rojo Vela | E33: Clausura 2025 | F33: 45838 | G33: 0 | H33: 39524 | I33: =_xlfn.FLOOR.MATH(M33)&" años "&P33&" meses" -> 18 años 0 meses | J33: =F33-$K$1 -> -266 | K33: =J33 -> -266 | L33: =$K$1-H33 -> 6580 | M33: =L33/365 -> 18.027397 | N33: =_xlfn.FLOOR.MATH(M33) -> 18 | O33: =L33-(N33*365) -> 10 | P33: =_xlfn.FLOOR.MATH(O33/30) -> 0 | Q33: *Asociación Jalisco
A34: 32 | B34: William Iván | C34: Rojo Vela | E34: Clausura 2025 | F34: 45838 | G34: 0 | H34: 40061 | I34: =_xlfn.FLOOR.MATH(M34)&" años "&P34&" meses" -> 16 años 6 meses | J34: =F34-$K$1 -> -266 | K34: =J34 -> -266 | L34: =$K$1-H34 -> 6043 | M34: =L34/365 -> 16.556164 | N34: =_xlfn.FLOOR.MATH(M34) -> 16 | O34: =L34-(N34*365) -> 203 | P34: =_xlfn.FLOOR.MATH(O34/30) -> 6
A35: 33 | B35: Ronaldo | C35: Sánchez Pérez | E35: Clausura 2025 | F35: 45838 | G35: 0 | H35: 39831 | I35: =_xlfn.FLOOR.MATH(M35)&" años "&P35&" meses" -> 17 años 2 meses | J35: =F35-$K$1 -> -266 | K35: =J35 -> -266 | L35: =$K$1-H35 -> 6273 | M35: =L35/365 -> 17.186301 | N35: =_xlfn.FLOOR.MATH(M35) -> 17 | O35: =L35-(N35*365) -> 68 | P35: =_xlfn.FLOOR.MATH(O35/30) -> 2
A36: 34 | B36: Gael Sebastián | C36: Solorio Jacobo | E36: Clausura 2025 | F36: 45838 | G36: 0 | H36: 39843 | I36: =_xlfn.FLOOR.MATH(M36)&" años "&P36&" meses" -> 17 años 1 meses | J36: =F36-$K$1 -> -266 | K36: =J36 -> -266 | L36: =$K$1-H36 -> 6261 | M36: =L36/365 -> 17.153425 | N36: =_xlfn.FLOOR.MATH(M36) -> 17 | O36: =L36-(N36*365) -> 56 | P36: =_xlfn.FLOOR.MATH(O36/30) -> 1
A37: 35 | B37: Julián | C37: Strietzel García | E37: Clausura 2025 | F37: 45838 | G37: 0 | H37: 40282 | I37: =_xlfn.FLOOR.MATH(M37)&" años "&P37&" meses" -> 15 años 11 meses | J37: =F37-$K$1 -> -266 | K37: =J37 -> -266 | L37: =$K$1-H37 -> 5822 | M37: =L37/365 -> 15.950685 | N37: =_xlfn.FLOOR.MATH(M37) -> 15 | O37: =L37-(N37*365) -> 347 | P37: =_xlfn.FLOOR.MATH(O37/30) -> 11
A38: 36 | B38: Ángel Daniel | C38: Uscanga García | E38: Clausura 2025 | F38: 45838 | G38: 0 | H38: 39836 | I38: =_xlfn.FLOOR.MATH(M38)&" años "&P38&" meses" -> 17 años 2 meses | J38: =F38-$K$1 -> -266 | K38: =J38 -> -266 | L38: =$K$1-H38 -> 6268 | M38: =L38/365 -> 17.172603 | N38: =_xlfn.FLOOR.MATH(M38) -> 17 | O38: =L38-(N38*365) -> 63 | P38: =_xlfn.FLOOR.MATH(O38/30) -> 2
A39: 37 | B39: José Luis | C39: Velázquez de León | E39: Clausura 2025 | F39: 45838 | G39: 0 | H39: 40222 | I39: =_xlfn.FLOOR.MATH(M39)&" años "&P39&" meses" -> 16 años 1 meses | J39: =F39-$K$1 -> -266 | K39: =J39 -> -266 | L39: =$K$1-H39 -> 5882 | M39: =L39/365 -> 16.115068 | N39: =_xlfn.FLOOR.MATH(M39) -> 16 | O39: =L39-(N39*365) -> 42 | P39: =_xlfn.FLOOR.MATH(O39/30) -> 1
A40: 38 | B40: Horacio Enrique | C40: Villarruel González | E40: Clausura 2024 | F40: 45473 | G40: 0 | H40: 39486 | I40: =_xlfn.FLOOR.MATH(M40)&" años "&P40&" meses" -> 18 años 1 meses | J40: =F40-$K$1 -> -631 | K40: =J40 -> -631 | L40: =$K$1-H40 -> 6618 | M40: =L40/365 -> 18.131507 | N40: =_xlfn.FLOOR.MATH(M40) -> 18 | O40: =L40-(N40*365) -> 48 | P40: =_xlfn.FLOOR.MATH(O40/30) -> 1

Sheet Femenil
A1: Femenil | K1: =TODAY() -> 46104
A2: NO. | B2: NOMBRE | C2: APELLIDOS | D2: NUI | E2: VIGENCIA | G2: SALARIO (MENSUAL) | H2: FECHA DE NACIMIENTO | I2: EDAD | J2: ESTATUS | K2: DÍAS RESTANTES DE CONTRATO
A3: 1 | B3: Susan Yanet | C3: Bejarano Rodríguez | E3: Clausura 2024 | F3: 45473 | G3: 40000 | H3: 34918 | I3: =_xlfn.FLOOR.MATH(M3)&" años "&P3&" meses" -> 30 años 7 meses | J3: =F3-$K$1 -> -631 | K3: =J3 -> -631 | L3: =$K$1-H3 -> 11186 | M3: =L3/365 -> 30.646575 | N3: =_xlfn.FLOOR.MATH(M3) -> 30 | O3: =L3-(N3*365) -> 236 | P3: =_xlfn.FLOOR.MATH(O3/30) -> 7
A4: 2 | B4: Brenda Damaris | C4: Ceren Delgado | E4: Clausura 2026 | F4: 46203 | G4: 40000 | H4: 36062 | I4: =_xlfn.FLOOR.MATH(M4)&" años "&P4&" meses" -> 27 años 6 meses | J4: =F4-$K$1 -> 99 | K4: =J4 -> 99 | L4: =$K$1-H4 -> 10042 | M4: =L4/365 -> 27.512329 | N4: =_xlfn.FLOOR.MATH(M4) -> 27 | O4: =L4-(N4*365) -> 187 | P4: =_xlfn.FLOOR.MATH(O4/30) -> 6
A5: 3 | B5: Selene Deyanira | C5: Cortés Valero | E5: Apertura 2024 | F5: 45657 | G5: 35000 | H5: 36071 | I5: =_xlfn.FLOOR.MATH(M5)&" años "&P5&" meses" -> 27 años 5 meses | J5: =F5-$K$1 -> -447 | K5: =J5 -> -447 | L5: =$K$1-H5 -> 10033 | M5: =L5/365 -> 27.487671 | N5: =_xlfn.FLOOR.MATH(M5) -> 27 | O5: =L5-(N5*365) -> 178 | P5: =_xlfn.FLOOR.MATH(O5/30) -> 5
A6: 4 | B6: Daniela María | C6: Cruz Mejía | E6: Apertura 2024 | F6: 45657 | G6: 40000 | H6: 33305 | I6: =_xlfn.FLOOR.MATH(M6)&" años "&P6&" meses" -> 35 años 0 meses | J6: =F6-$K$1 -> -447 | K6: =J6 -> -447 | L6: =$K$1-H6 -> 12799 | M6: =L6/365 -> 35.065753 | N6: =_xlfn.FLOOR.MATH(M6) -> 35 | O6: =L6-(N6*365) -> 24 | P6: =_xlfn.FLOOR.MATH(O6/30) -> 0
A7: 5 | B7: Alexa Daniela | C7: Curiel Sánchez | E7: Clausura 2025 | F7: 45838 | G7: 12500 | H7: 38091 | I7: =_xlfn.FLOOR.MATH(M7)&" años "&P7&" meses" -> 21 años 11 meses | J7: =F7-$K$1 -> -266 | K7: =J7 -> -266 | L7: =$K$1-H7 -> 8013 | M7: =L7/365 -> 21.953425 | N7: =_xlfn.FLOOR.MATH(M7) -> 21 | O7: =L7-(N7*365) -> 348 | P7: =_xlfn.FLOOR.MATH(O7/30) -> 11 | Q7: *checar mins
A8: 6 | B8: Kayla Laurynn | C8: Fernández Harvey | E8: Apertura 2025 | F8: 46022 | G8: 44000 | H8: 36991 | I8: =_xlfn.FLOOR.MATH(M8)&" años "&P8&" meses" -> 24 años 11 meses | J8: =F8-$K$1 -> -82 | K8: =J8 -> -82 | L8: =$K$1-H8 -> 9113 | M8: =L8/365 -> 24.967123 | N8: =_xlfn.FLOOR.MATH(M8) -> 24 | O8: =L8-(N8*365) -> 353 | P8: =_xlfn.FLOOR.MATH(O8/30) -> 11
A9: 7 | B9: Alejandra | C9: Franco Gómez | E9: Clausura 2024 | F9: 45473 | G9: 25000 | H9: 35036 | I9: =_xlfn.FLOOR.MATH(M9)&" años "&P9&" meses" -> 30 años 3 meses | J9: =F9-$K$1 -> -631 | K9: =J9 -> -631 | L9: =$K$1-H9 -> 11068 | M9: =L9/365 -> 30.323288 | N9: =_xlfn.FLOOR.MATH(M9) -> 30 | O9: =L9-(N9*365) -> 118 | P9: =_xlfn.FLOOR.MATH(O9/30) -> 3
A10: 8 | B10: Karen Andrea | C10: García Márquez | E10: Clausura 2024 | F10: 45473 | G10: 28000 | H10: 33911 | I10: =_xlfn.FLOOR.MATH(M10)&" años "&P10&" meses" -> 33 años 4 meses | J10: =F10-$K$1 -> -631 | K10: =J10 -> -631 | L10: =$K$1-H10 -> 12193 | M10: =L10/365 -> 33.405479 | N10: =_xlfn.FLOOR.MATH(M10) -> 33 | O10: =L10-(N10*365) -> 148 | P10: =_xlfn.FLOOR.MATH(O10/30) -> 4
A11: 9 | B11: Marcia Paola | C11: García Ramírez | E11: Clausura 2025 | F11: 45838 | G11: 22000 | H11: 38075 | I11: =_xlfn.FLOOR.MATH(M11)&" años "&P11&" meses" -> 21 años 12 meses | J11: =F11-$K$1 -> -266 | K11: =J11 -> -266 | L11: =$K$1-H11 -> 8029 | M11: =L11/365 -> 21.99726 | N11: =_xlfn.FLOOR.MATH(M11) -> 21 | O11: =L11-(N11*365) -> 364 | P11: =_xlfn.FLOOR.MATH(O11/30) -> 12 | Q11: *Sueldo cambia en CL 24 CHECAR MINS
A12: 10 | B12: Valeria Sarahi | C12: González Munguía | E12: Clausura 2025 | F12: 45838 | G12: 8000 | H12: 38413 | I12: =_xlfn.FLOOR.MATH(M12)&" años "&P12&" meses" -> 21 años 0 meses | J12: =F12-$K$1 -> -266 | K12: =J12 -> -266 | L12: =$K$1-H12 -> 7691 | M12: =L12/365 -> 21.071233 | N12: =_xlfn.FLOOR.MATH(M12) -> 21 | O12: =L12-(N12*365) -> 26 | P12: =_xlfn.FLOOR.MATH(O12/30) -> 0
A13: 11 | B13: Alejandra | C13: Lomelí Franco | E13: Clausura 2025 | F13: 45838 | G13: 20000 | H13: 38168 | I13: =_xlfn.FLOOR.MATH(M13)&" años "&P13&" meses" -> 21 años 9 meses | J13: =F13-$K$1 -> -266 | K13: =J13 -> -266 | L13: =$K$1-H13 -> 7936 | M13: =L13/365 -> 21.742466 | N13: =_xlfn.FLOOR.MATH(M13) -> 21 | O13: =L13-(N13*365) -> 271 | P13: =_xlfn.FLOOR.MATH(O13/30) -> 9
